Workbook

Sheet Dashboard
B1: Student Leader Deployment Dashboard
B2: ="Updated automatically from the Deployments, Activities and Students sheets · As of "&TEXT(TODAY(),"d mmm yyyy") -> Updated automatically from the Deployments, Activities and Students sheets · As of 22 Oct 2026
B4: STUDENT LEADERS | C4: DEPLOYED AT LEAST ONCE | E4: NOT YET DEPLOYED | G4: HIGH LOAD | I4: ACTIVITIES | L4: ACTIVE DEPLOYMENTS | M4: OPEN SLOTS | O4: DATA ISSUES
B5: =COUNTIF(Students!$A$2:$A$301,"?*") -> 1 | C5: =COUNTIF(Students!$I$2:$I$301,"Deployed")+COUNTIF(Students!$I$2:$I$301,"High load") -> 1 | E5: =COUNTIF(Students!$I$2:$I$301,"Not deployed") -> 0 | G5: =COUNTIF(Students!$I$2:$I$301,"High load") -> 0 | I5: =COUNTIF(Activities!$A$2:$A$201,"?*") -> 1 | L5: =COUNTIFS(Deployments!$A$2:$A$1001,"?*",Deployments!$D$2:$D$1001,"<>Withdrawn") -> 1 | M5: =SUM(Activities!$K$2:$K$201) -> 11 | O5: =COUNTIFS(Deployments!$L$2:$L$1001,"?*",Deployments!$L$2:$L$1001,"<>OK") -> 0
B6: =COUNTIF(Setup!$E$2:$E$60,"?*")&" form classes" -> 5 form classes | C6: =IF(B5=0,"",TEXT(C5/B5,"0%")&" of leaders") -> 100% of leaders | E6: =IF(B5=0,"",TEXT(E5/B5,"0%")&" of leaders") -> 0% of leaders | G6: ="at "&Setup!$H$2&"+ deployments" -> at 4+ deployments | I6: =COUNTIF(Activities!$N$2:$N$201,"Upcoming")&" in next "&Setup!$H$3&" days" -> 0 in next 14 days | L6: =TEXT(SUM(Deployments!$K$2:$K$1001),"#,##0.0")&" leader-hours" -> 3.5 leader-hours | M6: =(COUNTIF(Activities!$M$2:$M$201,"Short")+COUNTIF(Activities!$M$2:$M$201,"Unstaffed"))&" activities short" -> 1 activities short | O6: ="see Deployments › Check" -> see Deployments › Check
B8: Leader load — how evenly are leaders deployed? | L8: By form class
B9: Deployments per leader | C9: Leaders | D9: % of roster | L9: Form class | M9: Leaders | N9: Deployed | O9: Not yet | P9: Deployments
B10: 0 — not yet deployed | C10: =COUNTIFS(Students!$A$2:$A$301,"?*",Students!$F$2:$F$301,"0") -> 0 | D10: =IF($B$5=0,0,C10/$B$5) -> 0 | L10: =IF(Setup!$E$2="","",Setup!$E$2) -> 301 | M10: =IF($L10="","",COUNTIF(Students!$C$2:$C$301,$L10)) -> 0 | N10: =IF($L10="","",COUNTIFS(Students!$C$2:$C$301,$L10,Students!$F$2:$F$301,">0")) -> 0 | O10: =IF($L10="","",M10-N10) -> 0 | P10: =IF($L10="","",SUMIF(Students!$C$2:$C$301,$L10,Students!$F$2:$F$301)) -> 0
B11: 1 | C11: =COUNTIFS(Students!$A$2:$A$301,"?*",Students!$F$2:$F$301,"1") -> 1 | D11: =IF($B$5=0,0,C11/$B$5) -> 1 | L11: =IF(Setup!$E$3="","",Setup!$E$3) -> 302 | M11: =IF($L11="","",COUNTIF(Students!$C$2:$C$301,$L11)) -> 0 | N11: =IF($L11="","",COUNTIFS(Students!$C$2:$C$301,$L11,Students!$F$2:$F$301,">0")) -> 0 | O11: =IF($L11="","",M11-N11) -> 0 | P11: =IF($L11="","",SUMIF(Students!$C$2:$C$301,$L11,Students!$F$2:$F$301)) -> 0
B12: 2 | C12: =COUNTIFS(Students!$A$2:$A$301,"?*",Students!$F$2:$F$301,"2") -> 0 | D12: =IF($B$5=0,0,C12/$B$5) -> 0 | L12: =IF(Setup!$E$4="","",Setup!$E$4) -> 303 | M12: =IF($L12="","",COUNTIF(Students!$C$2:$C$301,$L12)) -> 1 | N12: =IF($L12="","",COUNTIFS(Students!$C$2:$C$301,$L12,Students!$F$2:$F$301,">0")) -> 1 | O12: =IF($L12="","",M12-N12) -> 0 | P12: =IF($L12="","",SUMIF(Students!$C$2:$C$301,$L12,Students!$F$2:$F$301)) -> 1
B13: 3 | C13: =COUNTIFS(Students!$A$2:$A$301,"?*",Students!$F$2:$F$301,"3") -> 0 | D13: =IF($B$5=0,0,C13/$B$5) -> 0 | L13: =IF(Setup!$E$5="","",Setup!$E$5) -> 304 | M13: =IF($L13="","",COUNTIF(Students!$C$2:$C$301,$L13)) -> 0 | N13: =IF($L13="","",COUNTIFS(Students!$C$2:$C$301,$L13,Students!$F$2:$F$301,">0")) -> 0 | O13: =IF($L13="","",M13-N13) -> 0 | P13: =IF($L13="","",SUMIF(Students!$C$2:$C$301,$L13,Students!$F$2:$F$301)) -> 0
B14: 4 or more | C14: =COUNTIFS(Students!$A$2:$A$301,"?*",Students!$F$2:$F$301,">=4") -> 0 | D14: =IF($B$5=0,0,C14/$B$5) -> 0 | L14: =IF(Setup!$E$6="","",Setup!$E$6) -> 305 | M14: =IF($L14="","",COUNTIF(Students!$C$2:$C$301,$L14)) -> 0 | N14: =IF($L14="","",COUNTIFS(Students!$C$2:$C$301,$L14,Students!$F$2:$F$301,">0")) -> 0 | O14: =IF($L14="","",M14-N14) -> 0 | P14: =IF($L14="","",SUMIF(Students!$C$2:$C$301,$L14,Students!$F$2:$F$301)) -> 0
L15: =IF(Setup!$E$7="","",Setup!$E$7) | M15: =IF($L15="","",COUNTIF(Students!$C$2:$C$301,$L15)) | N15: =IF($L15="","",COUNTIFS(Students!$C$2:$C$301,$L15,Students!$F$2:$F$301,">0")) | O15: =IF($L15="","",M15-N15) | P15: =IF($L15="","",SUMIF(Students!$C$2:$C$301,$L15,Students!$F$2:$F$301))
L16: =IF(Setup!$E$8="","",Setup!$E$8) | M16: =IF($L16="","",COUNTIF(Students!$C$2:$C$301,$L16)) | N16: =IF($L16="","",COUNTIFS(Students!$C$2:$C$301,$L16,Students!$F$2:$F$301,">0")) | O16: =IF($L16="","",M16-N16) | P16: =IF($L16="","",SUMIF(Students!$C$2:$C$301,$L16,Students!$F$2:$F$301))
B17: By activity category | L17: =IF(Setup!$E$9="","",Setup!$E$9) | M17: =IF($L17="","",COUNTIF(Students!$C$2:$C$301,$L17)) | N17: =IF($L17="","",COUNTIFS(Students!$C$2:$C$301,$L17,Students!$F$2:$F$301,">0")) | O17: =IF($L17="","",M17-N17) | P17: =IF($L17="","",SUMIF(Students!$C$2:$C$301,$L17,Students!$F$2:$F$301))
B18: Category | C18: Activities | D18: Deployments | E18: Leader-hours | F18: Open slots | L18: =IF(Setup!$E$10="","",Setup!$E$10) | M18: =IF($L18="","",COUNTIF(Students!$C$2:$C$301,$L18)) | N18: =IF($L18="","",COUNTIFS(Students!$C$2:$C$301,$L18,Students!$F$2:$F$301,">0")) | O18: =IF($L18="","",M18-N18) | P18: =IF($L18="","",SUMIF(Students!$C$2:$C$301,$L18,Students!$F$2:$F$301))
B19: =IF(Setup!$A$2="","",Setup!$A$2) -> Ceremony | C19: =IF($B19="","",COUNTIF(Activities!$B$2:$B$201,$B19)) -> 1 | D19: =IF($B19="","",COUNTIFS(Deployments!$H$2:$H$1001,$B19,Deployments!$D$2:$D$1001,"<>Withdrawn")) -> 1 | E19: =IF($B19="","",SUMIF(Deployments!$H$2:$H$1001,$B19,Deployments!$K$2:$K$1001)) -> 3.5 | F19: =IF($B19="","",SUMIF(Activities!$B$2:$B$201,$B19,Activities!$K$2:$K$201)) -> 11 | L19: =IF(Setup!$E$11="","",Setup!$E$11) | M19: =IF($L19="","",COUNTIF(Students!$C$2:$C$301,$L19)) | N19: =IF($L19="","",COUNTIFS(Students!$C$2:$C$301,$L19,Students!$F$2:$F$301,">0")) | O19: =IF($L19="","",M19-N19) | P19: =IF($L19="","",SUMIF(Students!$C$2:$C$301,$L19,Students!$F$2:$F$301))
B20: =IF(Setup!$A$3="","",Setup!$A$3) -> School Event | C20: =IF($B20="","",COUNTIF(Activities!$B$2:$B$201,$B20)) -> 0 | D20: =IF($B20="","",COUNTIFS(Deployments!$H$2:$H$1001,$B20,Deployments!$D$2:$D$1001,"<>Withdrawn")) -> 0 | E20: =IF($B20="","",SUMIF(Deployments!$H$2:$H$1001,$B20,Deployments!$K$2:$K$1001)) -> 0 | F20: =IF($B20="","",SUMIF(Activities!$B$2:$B$201,$B20,Activities!$K$2:$K$201)) -> 0 | L20: =IF(Setup!$E$12="","",Setup!$E$12) | M20: =IF($L20="","",COUNTIF(Students!$C$2:$C$301,$L20)) | N20: =IF($L20="","",COUNTIFS(Students!$C$2:$C$301,$L20,Students!$F$2:$F$301,">0")) | O20: =IF($L20="","",M20-N20) | P20: =IF($L20="","",SUMIF(Students!$C$2:$C$301,$L20,Students!$F$2:$F$301))
B21: =IF(Setup!$A$4="","",Setup!$A$4) -> Assembly | C21: =IF($B21="","",COUNTIF(Activities!$B$2:$B$201,$B21)) -> 0 | D21: =IF($B21="","",COUNTIFS(Deployments!$H$2:$H$1001,$B21,Deployments!$D$2:$D$1001,"<>Withdrawn")) -> 0 | E21: =IF($B21="","",SUMIF(Deployments!$H$2:$H$1001,$B21,Deployments!$K$2:$K$1001)) -> 0 | F21: =IF($B21="","",SUMIF(Activities!$B$2:$B$201,$B21,Activities!$K$2:$K$201)) -> 0 | L21: =IF(Setup!$E$13="","",Setup!$E$13) | M21: =IF($L21="","",COUNTIF(Students!$C$2:$C$301,$L21)) | N21: =IF($L21="","",COUNTIFS(Students!$C$2:$C$301,$L21,Students!$F$2:$F$301,">0")) | O21: =IF($L21="","",M21-N21) | P21: =IF($L21="","",SUMIF(Students!$C$2:$C$301,$L21,Students!$F$2:$F$301))
B22: =IF(Setup!$A$5="","",Setup!$A$5) -> Sports | C22: =IF($B22="","",COUNTIF(Activities!$B$2:$B$201,$B22)) -> 0 | D22: =IF($B22="","",COUNTIFS(Deployments!$H$2:$H$1001,$B22,Deployments!$D$2:$D$1001,"<>Withdrawn")) -> 0 | E22: =IF($B22="","",SUMIF(Deployments!$H$2:$H$1001,$B22,Deployments!$K$2:$K$1001)) -> 0 | F22: =IF($B22="","",SUMIF(Activities!$B$2:$B$201,$B22,Activities!$K$2:$K$201)) -> 0 | L22: =IF(Setup!$E$14="","",Setup!$E$14) | M22: =IF($L22="","",COUNTIF(Students!$C$2:$C$301,$L22)) | N22: =IF($L22="","",COUNTIFS(Students!$C$2:$C$301,$L22,Students!$F$2:$F$301,">0")) | O22: =IF($L22="","",M22-N22) | P22: =IF($L22="","",SUMIF(Students!$C$2:$C$301,$L22,Students!$F$2:$F$301))
B23: =IF(Setup!$A$6="","",Setup!$A$6) -> Community Service | C23: =IF($B23="","",COUNTIF(Activities!$B$2:$B$201,$B23)) -> 0 | D23: =IF($B23="","",COUNTIFS(Deployments!$H$2:$H$1001,$B23,Deployments!$D$2:$D$1001,"<>Withdrawn")) -> 0 | E23: =IF($B23="","",SUMIF(Deployments!$H$2:$H$1001,$B23,Deployments!$K$2:$K$1001)) -> 0 | F23: =IF($B23="","",SUMIF(Activities!$B$2:$B$201,$B23,Activities!$K$2:$K$201)) -> 0 | L23: =IF(Setup!$E$15="","",Setup!$E$15) | M23: =IF($L23="","",COUNTIF(Students!$C$2:$C$301,$L23)) | N23: =IF($L23="","",COUNTIFS(Students!$C$2:$C$301,$L23,Students!$F$2:$F$301,">0")) | O23: =IF($L23="","",M23-N23) | P23: =IF($L23="","",SUMIF(Students!$C$2:$C$301,$L23,Students!$F$2:$F$301))
B24: =IF(Setup!$A$7="","",Setup!$A$7) -> Open House | C24: =IF($B24="","",COUNTIF(Activities!$B$2:$B$201,$B24)) -> 0 | D24: =IF($B24="","",COUNTIFS(Deployments!$H$2:$H$1001,$B24,Deployments!$D$2:$D$1001,"<>Withdrawn")) -> 0 | E24: =IF($B24="","",SUMIF(Deployments!$H$2:$H$1001,$B24,Deployments!$K$2:$K$1001)) -> 0 | F24: =IF($B24="","",SUMIF(Activities!$B$2:$B$201,$B24,Activities!$K$2:$K$201)) -> 0 | L24: =IF(Setup!$E$16="","",Setup!$E$16) | M24: =IF($L24="","",COUNTIF(Students!$C$2:$C$301,$L24)) | N24: =IF($L24="","",COUNTIFS(Students!$C$2:$C$301,$L24,Students!$F$2:$F$301,">0")) | O24: =IF($L24="","",M24-N24) | P24: =IF($L24="","",SUMIF(Students!$C$2:$C$301,$L24,Students!$F$2:$F$301))
B25: =IF(Setup!$A$8="","",Setup!$A$8) -> Camp | C25: =IF($B25="","",COUNTIF(Activities!$B$2:$B$201,$B25)) -> 0 | D25: =IF($B25="","",COUNTIFS(Deployments!$H$2:$H$1001,$B25,Deployments!$D$2:$D$1001,"<>Withdrawn")) -> 0 | E25: =IF($B25="","",SUMIF(Deployments!$H$2:$H$1001,$B25,Deployments!$K$2:$K$1001)) -> 0 | F25: =IF($B25="","",SUMIF(Activities!$B$2:$B$201,$B25,Activities!$K$2:$K$201)) -> 0
B26: =IF(Setup!$A$9="","",Setup!$A$9) -> External | C26: =IF($B26="","",COUNTIF(Activities!$B$2:$B$201,$B26)) -> 0 | D26: =IF($B26="","",COUNTIFS(Deployments!$H$2:$H$1001,$B26,Deployments!$D$2:$D$1001,"<>Withdrawn")) -> 0 | E26: =IF($B26="","",SUMIF(Deployments!$H$2:$H$1001,$B26,Deployments!$K$2:$K$1001)) -> 0 | F26: =IF($B26="","",SUMIF(Activities!$B$2:$B$201,$B26,Activities!$K$2:$K$201)) -> 0
B28: Charts
B46: Most deployed — check for over-reliance | L46: Not yet deployed — give them a turn
B47: Leader | C47: Form class | D47: Deployments | E47: Leader-hours | F47: Latest | L47: Leader | M47: Form class | N47: Group
B48: =IFERROR(INDEX(Students!$A$2:$A$301,MATCH(LARGE(Students!$J$2:$J$301,1),Students!$J$2:$J$301,0)),"") -> Tan Wei Ling | C48: =IF($B48="","",INDEX(Students!$C$2:$C$301,MATCH(LARGE(Students!$J$2:$J$301,1),Students!$J$2:$J$301,0))) -> 303 | D48: =IF($B48="","",INDEX(Students!$F$2:$F$301,MATCH(LARGE(Students!$J$2:$J$301,1),Students!$J$2:$J$301,0))) -> 1 | E48: =IF($B48="","",INDEX(Students!$G$2:$G$301,MATCH(LARGE(Students!$J$2:$J$301,1),Students!$J$2:$J$301,0))) -> 3.5 | F48: =IF($B48="","",INDEX(Students!$H$2:$H$301,MATCH(LARGE(Students!$J$2:$J$301,1),Students!$J$2:$J$301,0))) -> 46311 | L48: =IFERROR(INDEX(Students!$A$2:$A$301,MATCH(1,Students!$K$2:$K$301,0)),"") | M48: =IF($L48="","",INDEX(Students!$C$2:$C$301,MATCH(1,Students!$K$2:$K$301,0))) | N48: =IF($L48="","",INDEX(Students!$D$2:$D$301,MATCH(1,Students!$K$2:$K$301,0)))
B49: =IFERROR(INDEX(Students!$A$2:$A$301,MATCH(LARGE(Students!$J$2:$J$301,2),Students!$J$2:$J$301,0)),"") | C49: =IF($B49="","",INDEX(Students!$C$2:$C$301,MATCH(LARGE(Students!$J$2:$J$301,2),Students!$J$2:$J$301,0))) | D49: =IF($B49="","",INDEX(Students!$F$2:$F$301,MATCH(LARGE(Students!$J$2:$J$301,2),Students!$J$2:$J$301,0))) | E49: =IF($B49="","",INDEX(Students!$G$2:$G$301,MATCH(LARGE(Students!$J$2:$J$301,2),Students!$J$2:$J$301,0))) | F49: =IF($B49="","",INDEX(Students!$H$2:$H$301,MATCH(LARGE(Students!$J$2:$J$301,2),Students!$J$2:$J$301,0))) | L49: =IFERROR(INDEX(Students!$A$2:$A$301,MATCH(2,Students!$K$2:$K$301,0)),"") | M49: =IF($L49="","",INDEX(Students!$C$2:$C$301,MATCH(2,Students!$K$2:$K$301,0))) | N49: =IF($L49="","",INDEX(Students!$D$2:$D$301,MATCH(2,Students!$K$2:$K$301,0)))
B50: =IFERROR(INDEX(Students!$A$2:$A$301,MATCH(LARGE(Students!$J$2:$J$301,3),Students!$J$2:$J$301,0)),"") | C50: =IF($B50="","",INDEX(Students!$C$2:$C$301,MATCH(LARGE(Students!$J$2:$J$301,3),Students!$J$2:$J$301,0))) | D50: =IF($B50="","",INDEX(Students!$F$2:$F$301,MATCH(LARGE(Students!$J$2:$J$301,3),Students!$J$2:$J$301,0))) | E50: =IF($B50="","",INDEX(Students!$G$2:$G$301,MATCH(LARGE(Students!$J$2:$J$301,3),Students!$J$2:$J$301,0))) | F50: =IF($B50="","",INDEX(Students!$H$2:$H$301,MATCH(LARGE(Students!$J$2:$J$301,3),Students!$J$2:$J$301,0))) | L50: =IFERROR(INDEX(Students!$A$2:$A$301,MATCH(3,Students!$K$2:$K$301,0)),"") | M50: =IF($L50="","",INDEX(Students!$C$2:$C$301,MATCH(3,Students!$K$2:$K$301,0))) | N50: =IF($L50="","",INDEX(Students!$D$2:$D$301,MATCH(3,Students!$K$2:$K$301,0)))
B51: =IFERROR(INDEX(Students!$A$2:$A$301,MATCH(LARGE(Students!$J$2:$J$301,4),Students!$J$2:$J$301,0)),"") | C51: =IF($B51="","",INDEX(Students!$C$2:$C$301,MATCH(LARGE(Students!$J$2:$J$301,4),Students!$J$2:$J$301,0))) | D51: =IF($B51="","",INDEX(Students!$F$2:$F$301,MATCH(LARGE(Students!$J$2:$J$301,4),Students!$J$2:$J$301,0))) | E51: =IF($B51="","",INDEX(Students!$G$2:$G$301,MATCH(LARGE(Students!$J$2:$J$301,4),Students!$J$2:$J$301,0))) | F51: =IF($B51="","",INDEX(Students!$H$2:$H$301,MATCH(LARGE(Students!$J$2:$J$301,4),Students!$J$2:$J$301,0))) | L51: =IFERROR(INDEX(Students!$A$2:$A$301,MATCH(4,Students!$K$2:$K$301,0)),"") | M51: =IF($L51="","",INDEX(Students!$C$2:$C$301,MATCH(4,Students!$K$2:$K$301,0))) | N51: =IF($L51="","",INDEX(Students!$D$2:$D$301,MATCH(4,Students!$K$2:$K$301,0)))
B52: =IFERROR(INDEX(Students!$A$2:$A$301,MATCH(LARGE(Students!$J$2:$J$301,5),Students!$J$2:$J$301,0)),"") | C52: =IF($B52="","",INDEX(Students!$C$2:$C$301,MATCH(LARGE(Students!$J$2:$J$301,5),Students!$J$2:$J$301,0))) | D52: =IF($B52="","",INDEX(Students!$F$2:$F$301,MATCH(LARGE(Students!$J$2:$J$301,5),Students!$J$2:$J$301,0))) | E52: =IF($B52="","",INDEX(Students!$G$2:$G$301,MATCH(LARGE(Students!$J$2:$J$301,5),Students!$J$2:$J$301,0))) | F52: =IF($B52="","",INDEX(Students!$H$2:$H$301,MATCH(LARGE(Students!$J$2:$J$301,5),Students!$J$2:$J$301,0))) | L52: =IFERROR(INDEX(Students!$A$2:$A$301,MATCH(5,Students!$K$2:$K$301,0)),"") | M52: =IF($L52="","",INDEX(Students!$C$2:$C$301,MATCH(5,Students!$K$2:$K$301,0))) | N52: =IF($L52="","",INDEX(Students!$D$2:$D$301,MATCH(5,Students!$K$2:$K$301,0)))
B53: =IFERROR(INDEX(Students!$A$2:$A$301,MATCH(LARGE(Students!$J$2:$J$301,6),Students!$J$2:$J$301,0)),"") | C53: =IF($B53="","",INDEX(Students!$C$2:$C$301,MATCH(LARGE(Students!$J$2:$J$301,6),Students!$J$2:$J$301,0))) | D53: =IF($B53="","",INDEX(Students!$F$2:$F$301,MATCH(LARGE(Students!$J$2:$J$301,6),Students!$J$2:$J$301,0))) | E53: =IF($B53="","",INDEX(Students!$G$2:$G$301,MATCH(LARGE(Students!$J$2:$J$301,6),Students!$J$2:$J$301,0))) | F53: =IF($B53="","",INDEX(Students!$H$2:$H$301,MATCH(LARGE(Students!$J$2:$J$301,6),Students!$J$2:$J$301,0))) | L53: =IFERROR(INDEX(Students!$A$2:$A$301,MATCH(6,Students!$K$2:$K$301,0)),"") | M53: =IF($L53="","",INDEX(Students!$C$2:$C$301,MATCH(6,Students!$K$2:$K$301,0))) | N53: =IF($L53="","",INDEX(Students!$D$2:$D$301,MATCH(6,Students!$K$2:$K$301,0)))
B54: =IFERROR(INDEX(Students!$A$2:$A$301,MATCH(LARGE(Students!$J$2:$J$301,7),Students!$J$2:$J$301,0)),"") | C54: =IF($B54="","",INDEX(Students!$C$2:$C$301,MATCH(LARGE(Students!$J$2:$J$301,7),Students!$J$2:$J$301,0))) | D54: =IF($B54="","",INDEX(Students!$F$2:$F$301,MATCH(LARGE(Students!$J$2:$J$301,7),Students!$J$2:$J$301,0))) | E54: =IF($B54="","",INDEX(Students!$G$2:$G$301,MATCH(LARGE(Students!$J$2:$J$301,7),Students!$J$2:$J$301,0))) | F54: =IF($B54="","",INDEX(Students!$H$2:$H$301,MATCH(LARGE(Students!$J$2:$J$301,7),Students!$J$2:$J$301,0))) | L54: =IFERROR(INDEX(Students!$A$2:$A$301,MATCH(7,Students!$K$2:$K$301,0)),"") | M54: =IF($L54="","",INDEX(Students!$C$2:$C$301,MATCH(7,Students!$K$2:$K$301,0))) | N54: =IF($L54="","",INDEX(Students!$D$2:$D$301,MATCH(7,Students!$K$2:$K$301,0)))
B55: =IFERROR(INDEX(Students!$A$2:$A$301,MATCH(LARGE(Students!$J$2:$J$301,8),Students!$J$2:$J$301,0)),"") | C55: =IF($B55="","",INDEX(Students!$C$2:$C$301,MATCH(LARGE(Students!$J$2:$J$301,8),Students!$J$2:$J$301,0))) | D55: =IF($B55="","",INDEX(Students!$F$2:$F$301,MATCH(LARGE(Students!$J$2:$J$301,8),Students!$J$2:$J$301,0))) | E55: =IF($B55="","",INDEX(Students!$G$2:$G$301,MATCH(LARGE(Students!$J$2:$J$301,8),Students!$J$2:$J$301,0))) | F55: =IF($B55="","",INDEX(Students!$H$2:$H$301,MATCH(LARGE(Students!$J$2:$J$301,8),Students!$J$2:$J$301,0))) | L55: =IFERROR(INDEX(Students!$A$2:$A$301,MATCH(8,Students!$K$2:$K$301,0)),"") | M55: =IF($L55="","",INDEX(Students!$C$2:$C$301,MATCH(8,Students!$K$2:$K$301,0))) | N55: =IF($L55="","",INDEX(Students!$D$2:$D$301,MATCH(8,Students!$K$2:$K$301,0)))
B56: =IFERROR(INDEX(Students!$A$2:$A$301,MATCH(LARGE(Students!$J$2:$J$301,9),Students!$J$2:$J$301,0)),"") | C56: =IF($B56="","",INDEX(Students!$C$2:$C$301,MATCH(LARGE(Students!$J$2:$J$301,9),Students!$J$2:$J$301,0))) | D56: =IF($B56="","",INDEX(Students!$F$2:$F$301,MATCH(LARGE(Students!$J$2:$J$301,9),Students!$J$2:$J$301,0))) | E56: =IF($B56="","",INDEX(Students!$G$2:$G$301,MATCH(LARGE(Students!$J$2:$J$301,9),Students!$J$2:$J$301,0))) | F56: =IF($B56="","",INDEX(Students!$H$2:$H$301,MATCH(LARGE(Students!$J$2:$J$301,9),Students!$J$2:$J$301,0))) | L56: =IFERROR(INDEX(Students!$A$2:$A$301,MATCH(9,Students!$K$2:$K$301,0)),"") | M56: =IF($L56="","",INDEX(Students!$C$2:$C$301,MATCH(9,Students!$K$2:$K$301,0))) | N56: =IF($L56="","",INDEX(Students!$D$2:$D$301,MATCH(9,Students!$K$2:$K$301,0)))
B57: =IFERROR(INDEX(Students!$A$2:$A$301,MATCH(LARGE(Students!$J$2:$J$301,10),Students!$J$2:$J$301,0)),"") | C57: =IF($B57="","",INDEX(Students!$C$2:$C$301,MATCH(LARGE(Students!$J$2:$J$301,10),Students!$J$2:$J$301,0))) | D57: =IF($B57="","",INDEX(Students!$F$2:$F$301,MATCH(LARGE(Students!$J$2:$J$301,10),Students!$J$2:$J$301,0))) | E57: =IF($B57="","",INDEX(Students!$G$2:$G$301,MATCH(LARGE(Students!$J$2:$J$301,10),Students!$J$2:$J$301,0))) | F57: =IF($B57="","",INDEX(Students!$H$2:$H$301,MATCH(LARGE(Students!$J$2:$J$301,10),Students!$J$2:$J$301,0))) | L57: =IFERROR(INDEX(Students!$A$2:$A$301,MATCH(10,Students!$K$2:$K$301,0)),"") | M57: =IF($L57="","",INDEX(Students!$C$2:$C$301,MATCH(10,Students!$K$2:$K$301,0))) | N57: =IF($L57="","",INDEX(Students!$D$2:$D$301,MATCH(10,Students!$K$2:$K$301,0)))
L58: =IFERROR(INDEX(Students!$A$2:$A$301,MATCH(11,Students!$K$2:$K$301,0)),"") | M58: =IF($L58="","",INDEX(Students!$C$2:$C$301,MATCH(11,Students!$K$2:$K$301,0))) | N58: =IF($L58="","",INDEX(Students!$D$2:$D$301,MATCH(11,Students!$K$2:$K$301,0)))
L59: =IFERROR(INDEX(Students!$A$2:$A$301,MATCH(12,Students!$K$2:$K$301,0)),"") | M59: =IF($L59="","",INDEX(Students!$C$2:$C$301,MATCH(12,Students!$K$2:$K$301,0))) | N59: =IF($L59="","",INDEX(Students!$D$2:$D$301,MATCH(12,Students!$K$2:$K$301,0)))
L60: =IFERROR(INDEX(Students!$A$2:$A$301,MATCH(13,Students!$K$2:$K$301,0)),"") | M60: =IF($L60="","",INDEX(Students!$C$2:$C$301,MATCH(13,Students!$K$2:$K$301,0))) | N60: =IF($L60="","",INDEX(Students!$D$2:$D$301,MATCH(13,Students!$K$2:$K$301,0)))
...

Sheet Deployments
A1: Activity | B1: Student (Full Name) | C1: Role | D1: Status | E1: Hours Override | F1: Remarks | G1: Date | H1: Category | I1: Form Class | J1: Name | K1: Hours Credited | L1: Check
A2: Speech Day & Prize Giving | B2: Tan Wei Ling | C2: Emcee | D2: Confirmed | F2: Example row — overwrite or delete | G2: =IF($A2="","",IFERROR(IF(INDEX(Activities!$C$2:$C$201,MATCH($A2,Activities!$A$2:$A$201,0))="","",INDEX(Activities!$C$2:$C$201,MATCH($A2,Activities!$A$2:$A$201,0))),"")) -> 46311 | H2: =IF($A2="","",IFERROR(IF(INDEX(Activities!$B$2:$B$201,MATCH($A2,Activities!$A$2:$A$201,0))="","",INDEX(Activities!$B$2:$B$201,MATCH($A2,Activities!$A$2:$A$201,0))),"")) -> Ceremony | I2: =IF($B2="","",IFERROR(IF(INDEX(Students!$C$2:$C$301,MATCH($B2,Students!$A$2:$A$301,0))="","",INDEX(Students!$C$2:$C$301,MATCH($B2,Students!$A$2:$A$301,0))),"")) -> 303 | J2: =IF($B2="","",IFERROR(IF(INDEX(Students!$B$2:$B$301,MATCH($B2,Students!$A$2:$A$301,0))="","",INDEX(Students!$B$2:$B$301,MATCH($B2,Students!$A$2:$A$301,0))),"")) -> Wei Ling | K2: =IF($A2="","",IF(D2="Withdrawn",0,IF(E2<>"",N(E2),IFERROR(N(INDEX(Activities!$I$2:$I$201,MATCH($A2,Activities!$A$2:$A$201,0))),0)))) -> 3.5 | L2: =IF(AND($A2="",$B2=""),"",IF(ISNA(MATCH($A2,Activities!$A$2:$A$201,0)),"Unknown activity",IF(ISNA(MATCH($B2,Students!$A$2:$A$301,0)),"Unknown student",IF(D2="","No status",IF(COUNTIFS($A$2:$A$1001,$A2,$B$2:$B$1001,$B2)>1,"Duplicate",IF(AND(D2<>"Withdrawn",G2<>"",COUNTIFS($B$2:$B$1001,$B2,$G$2:$G$1001,G2,$D$2:$D$1001,"<>Withdrawn")>1),"Same-day clash","OK")))))) -> OK
G3: =IF($A3="","",IFERROR(IF(INDEX(Activities!$C$2:$C$201,MATCH($A3,Activities!$A$2:$A$201,0))="","",INDEX(Activities!$C$2:$C$201,MATCH($A3,Activities!$A$2:$A$201,0))),"")) | H3: =IF($A3="","",IFERROR(IF(INDEX(Activities!$B$2:$B$201,MATCH($A3,Activities!$A$2:$A$201,0))="","",INDEX(Activities!$B$2:$B$201,MATCH($A3,Activities!$A$2:$A$201,0))),"")) | I3: =IF($B3="","",IFERROR(IF(INDEX(Students!$C$2:$C$301,MATCH($B3,Students!$A$2:$A$301,0))="","",INDEX(Students!$C$2:$C$301,MATCH($B3,Students!$A$2:$A$301,0))),"")) | J3: =IF($B3="","",IFERROR(IF(INDEX(Students!$B$2:$B$301,MATCH($B3,Students!$A$2:$A$301,0))="","",INDEX(Students!$B$2:$B$301,MATCH($B3,Students!$A$2:$A$301,0))),"")) | K3: =IF($A3="","",IF(D3="Withdrawn",0,IF(E3<>"",N(E3),IFERROR(N(INDEX(Activities!$I$2:$I$201,MATCH($A3,Activities!$A$2:$A$201,0))),0)))) | L3: =IF(AND($A3="",$B3=""),"",IF(ISNA(MATCH($A3,Activities!$A$2:$A$201,0)),"Unknown activity",IF(ISNA(MATCH($B3,Students!$A$2:$A$301,0)),"Unknown student",IF(D3="","No status",IF(COUNTIFS($A$2:$A$1001,$A3,$B$2:$B$1001,$B3)>1,"Duplicate",IF(AND(D3<>"Withdrawn",G3<>"",COUNTIFS($B$2:$B$1001,$B3,$G$2:$G$1001,G3,$D$2:$D$1001,"<>Withdrawn")>1),"Same-day clash","OK"))))))
G4: =IF($A4="","",IFERROR(IF(INDEX(Activities!$C$2:$C$201,MATCH($A4,Activities!$A$2:$A$201,0))="","",INDEX(Activities!$C$2:$C$201,MATCH($A4,Activities!$A$2:$A$201,0))),"")) | H4: =IF($A4="","",IFERROR(IF(INDEX(Activities!$B$2:$B$201,MATCH($A4,Activities!$A$2:$A$201,0))="","",INDEX(Activities!$B$2:$B$201,MATCH($A4,Activities!$A$2:$A$201,0))),"")) | I4: =IF($B4="","",IFERROR(IF(INDEX(Students!$C$2:$C$301,MATCH($B4,Students!$A$2:$A$301,0))="","",INDEX(Students!$C$2:$C$301,MATCH($B4,Students!$A$2:$A$301,0))),"")) | J4: =IF($B4="","",IFERROR(IF(INDEX(Students!$B$2:$B$301,MATCH($B4,Students!$A$2:$A$301,0))="","",INDEX(Students!$B$2:$B$301,MATCH($B4,Students!$A$2:$A$301,0))),"")) | K4: =IF($A4="","",IF(D4="Withdrawn",0,IF(E4<>"",N(E4),IFERROR(N(INDEX(Activities!$I$2:$I$201,MATCH($A4,Activities!$A$2:$A$201,0))),0)))) | L4: =IF(AND($A4="",$B4=""),"",IF(ISNA(MATCH($A4,Activities!$A$2:$A$201,0)),"Unknown activity",IF(ISNA(MATCH($B4,Students!$A$2:$A$301,0)),"Unknown student",IF(D4="","No status",IF(COUNTIFS($A$2:$A$1001,$A4,$B$2:$B$1001,$B4)>1,"Duplicate",IF(AND(D4<>"Withdrawn",G4<>"",COUNTIFS($B$2:$B$1001,$B4,$G$2:$G$1001,G4,$D$2:$D$1001,"<>Withdrawn")>1),"Same-day clash","OK"))))))
G5: =IF($A5="","",IFERROR(IF(INDEX(Activities!$C$2:$C$201,MATCH($A5,Activities!$A$2:$A$201,0))="","",INDEX(Activities!$C$2:$C$201,MATCH($A5,Activities!$A$2:$A$201,0))),"")) | H5: =IF($A5="","",IFERROR(IF(INDEX(Activities!$B$2:$B$201,MATCH($A5,Activities!$A$2:$A$201,0))="","",INDEX(Activities!$B$2:$B$201,MATCH($A5,Activities!$A$2:$A$201,0))),"")) | I5: =IF($B5="","",IFERROR(IF(INDEX(Students!$C$2:$C$301,MATCH($B5,Students!$A$2:$A$301,0))="","",INDEX(Students!$C$2:$C$301,MATCH($B5,Students!$A$2:$A$301,0))),"")) | J5: =IF($B5="","",IFERROR(IF(INDEX(Students!$B$2:$B$301,MATCH($B5,Students!$A$2:$A$301,0))="","",INDEX(Students!$B$2:$B$301,MATCH($B5,Students!$A$2:$A$301,0))),"")) | K5: =IF($A5="","",IF(D5="Withdrawn",0,IF(E5<>"",N(E5),IFERROR(N(INDEX(Activities!$I$2:$I$201,MATCH($A5,Activities!$A$2:$A$201,0))),0)))) | L5: =IF(AND($A5="",$B5=""),"",IF(ISNA(MATCH($A5,Activities!$A$2:$A$201,0)),"Unknown activity",IF(ISNA(MATCH($B5,Students!$A$2:$A$301,0)),"Unknown student",IF(D5="","No status",IF(COUNTIFS($A$2:$A$1001,$A5,$B$2:$B$1001,$B5)>1,"Duplicate",IF(AND(D5<>"Withdrawn",G5<>"",COUNTIFS($B$2:$B$1001,$B5,$G$2:$G$1001,G5,$D$2:$D$1001,"<>Withdrawn")>1),"Same-day clash","OK"))))))
G6: =IF($A6="","",IFERROR(IF(INDEX(Activities!$C$2:$C$201,MATCH($A6,Activities!$A$2:$A$201,0))="","",INDEX(Activities!$C$2:$C$201,MATCH($A6,Activities!$A$2:$A$201,0))),"")) | H6: =IF($A6="","",IFERROR(IF(INDEX(Activities!$B$2:$B$201,MATCH($A6,Activities!$A$2:$A$201,0))="","",INDEX(Activities!$B$2:$B$201,MATCH($A6,Activities!$A$2:$A$201,0))),"")) | I6: =IF($B6="","",IFERROR(IF(INDEX(Students!$C$2:$C$301,MATCH($B6,Students!$A$2:$A$301,0))="","",INDEX(Students!$C$2:$C$301,MATCH($B6,Students!$A$2:$A$301,0))),"")) | J6: =IF($B6="","",IFERROR(IF(INDEX(Students!$B$2:$B$301,MATCH($B6,Students!$A$2:$A$301,0))="","",INDEX(Students!$B$2:$B$301,MATCH($B6,Students!$A$2:$A$301,0))),"")) | K6: =IF($A6="","",IF(D6="Withdrawn",0,IF(E6<>"",N(E6),IFERROR(N(INDEX(Activities!$I$2:$I$201,MATCH($A6,Activities!$A$2:$A$201,0))),0)))) | L6: =IF(AND($A6="",$B6=""),"",IF(ISNA(MATCH($A6,Activities!$A$2:$A$201,0)),"Unknown activity",IF(ISNA(MATCH($B6,Students!$A$2:$A$301,0)),"Unknown student",IF(D6="","No status",IF(COUNTIFS($A$2:$A$1001,$A6,$B$2:$B$1001,$B6)>1,"Duplicate",IF(AND(D6<>"Withdrawn",G6<>"",COUNTIFS($B$2:$B$1001,$B6,$G$2:$G$1001,G6,$D$2:$D$1001,"<>Withdrawn")>1),"Same-day clash","OK"))))))
G7: =IF($A7="","",IFERROR(IF(INDEX(Activities!$C$2:$C$201,MATCH($A7,Activities!$A$2:$A$201,0))="","",INDEX(Activities!$C$2:$C$201,MATCH($A7,Activities!$A$2:$A$201,0))),"")) | H7: =IF($A7="","",IFERROR(IF(INDEX(Activities!$B$2:$B$201,MATCH($A7,Activities!$A$2:$A$201,0))="","",INDEX(Activities!$B$2:$B$201,MATCH($A7,Activities!$A$2:$A$201,0))),"")) | I7: =IF($B7="","",IFERROR(IF(INDEX(Students!$C$2:$C$301,MATCH($B7,Students!$A$2:$A$301,0))="","",INDEX(Students!$C$2:$C$301,MATCH($B7,Students!$A$2:$A$301,0))),"")) | J7: =IF($B7="","",IFERROR(IF(INDEX(Students!$B$2:$B$301,MATCH($B7,Students!$A$2:$A$301,0))="","",INDEX(Students!$B$2:$B$301,MATCH($B7,Students!$A$2:$A$301,0))),"")) | K7: =IF($A7="","",IF(D7="Withdrawn",0,IF(E7<>"",N(E7),IFERROR(N(INDEX(Activities!$I$2:$I$201,MATCH($A7,Activities!$A$2:$A$201,0))),0)))) | L7: =IF(AND($A7="",$B7=""),"",IF(ISNA(MATCH($A7,Activities!$A$2:$A$201,0)),"Unknown activity",IF(ISNA(MATCH($B7,Students!$A$2:$A$301,0)),"Unknown student",IF(D7="","No status",IF(COUNTIFS($A$2:$A$1001,$A7,$B$2:$B$1001,$B7)>1,"Duplicate",IF(AND(D7<>"Withdrawn",G7<>"",COUNTIFS($B$2:$B$1001,$B7,$G$2:$G$1001,G7,$D$2:$D$1001,"<>Withdrawn")>1),"Same-day clash","OK"))))))
G8: =IF($A8="","",IFERROR(IF(INDEX(Activities!$C$2:$C$201,MATCH($A8,Activities!$A$2:$A$201,0))="","",INDEX(Activities!$C$2:$C$201,MATCH($A8,Activities!$A$2:$A$201,0))),"")) | H8: =IF($A8="","",IFERROR(IF(INDEX(Activities!$B$2:$B$201,MATCH($A8,Activities!$A$2:$A$201,0))="","",INDEX(Activities!$B$2:$B$201,MATCH($A8,Activities!$A$2:$A$201,0))),"")) | I8: =IF($B8="","",IFERROR(IF(INDEX(Students!$C$2:$C$301,MATCH($B8,Students!$A$2:$A$301,0))="","",INDEX(Students!$C$2:$C$301,MATCH($B8,Students!$A$2:$A$301,0))),"")) | J8: =IF($B8="","",IFERROR(IF(INDEX(Students!$B$2:$B$301,MATCH($B8,Students!$A$2:$A$301,0))="","",INDEX(Students!$B$2:$B$301,MATCH($B8,Students!$A$2:$A$301,0))),"")) | K8: =IF($A8="","",IF(D8="Withdrawn",0,IF(E8<>"",N(E8),IFERROR(N(INDEX(Activities!$I$2:$I$201,MATCH($A8,Activities!$A$2:$A$201,0))),0)))) | L8: =IF(AND($A8="",$B8=""),"",IF(ISNA(MATCH($A8,Activities!$A$2:$A$201,0)),"Unknown activity",IF(ISNA(MATCH($B8,Students!$A$2:$A$301,0)),"Unknown student",IF(D8="","No status",IF(COUNTIFS($A$2:$A$1001,$A8,$B$2:$B$1001,$B8)>1,"Duplicate",IF(AND(D8<>"Withdrawn",G8<>"",COUNTIFS($B$2:$B$1001,$B8,$G$2:$G$1001,G8,$D$2:$D$1001,"<>Withdrawn")>1),"Same-day clash","OK"))))))
G9: =IF($A9="","",IFERROR(IF(INDEX(Activities!$C$2:$C$201,MATCH($A9,Activities!$A$2:$A$201,0))="","",INDEX(Activities!$C$2:$C$201,MATCH($A9,Activities!$A$2:$A$201,0))),"")) | H9: =IF($A9="","",IFERROR(IF(INDEX(Activities!$B$2:$B$201,MATCH($A9,Activities!$A$2:$A$201,0))="","",INDEX(Activities!$B$2:$B$201,MATCH($A9,Activities!$A$2:$A$201,0))),"")) | I9: =IF($B9="","",IFERROR(IF(INDEX(Students!$C$2:$C$301,MATCH($B9,Students!$A$2:$A$301,0))="","",INDEX(Students!$C$2:$C$301,MATCH($B9,Students!$A$2:$A$301,0))),"")) | J9: =IF($B9="","",IFERROR(IF(INDEX(Students!$B$2:$B$301,MATCH($B9,Students!$A$2:$A$301,0))="","",INDEX(Students!$B$2:$B$301,MATCH($B9,Students!$A$2:$A$301,0))),"")) | K9: =IF($A9="","",IF(D9="Withdrawn",0,IF(E9<>"",N(E9),IFERROR(N(INDEX(Activities!$I$2:$I$201,MATCH($A9,Activities!$A$2:$A$201,0))),0)))) | L9: =IF(AND($A9="",$B9=""),"",IF(ISNA(MATCH($A9,Activities!$A$2:$A$201,0)),"Unknown activity",IF(ISNA(MATCH($B9,Students!$A$2:$A$301,0)),"Unknown student",IF(D9="","No status",IF(COUNTIFS($A$2:$A$1001,$A9,$B$2:$B$1001,$B9)>1,"Duplicate",IF(AND(D9<>"Withdrawn",G9<>"",COUNTIFS($B$2:$B$1001,$B9,$G$2:$G$1001,G9,$D$2:$D$1001,"<>Withdrawn")>1),"Same-day clash","OK"))))))
G10: =IF($A10="","",IFERROR(IF(INDEX(Activities!$C$2:$C$201,MATCH($A10,Activities!$A$2:$A$201,0))="","",INDEX(Activities!$C$2:$C$201,MATCH($A10,Activities!$A$2:$A$201,0))),"")) | H10: =IF($A10="","",IFERROR(IF(INDEX(Activities!$B$2:$B$201,MATCH($A10,Activities!$A$2:$A$201,0))="","",INDEX(Activities!$B$2:$B$201,MATCH($A10,Activities!$A$2:$A$201,0))),"")) | I10: =IF($B10="","",IFERROR(IF(INDEX(Students!$C$2:$C$301,MATCH($B10,Students!$A$2:$A$301,0))="","",INDEX(Students!$C$2:$C$301,MATCH($B10,Students!$A$2:$A$301,0))),"")) | J10: =IF($B10="","",IFERROR(IF(INDEX(Students!$B$2:$B$301,MATCH($B10,Students!$A$2:$A$301,0))="","",INDEX(Students!$B$2:$B$301,MATCH($B10,Students!$A$2:$A$301,0))),"")) | K10: =IF($A10="","",IF(D10="Withdrawn",0,IF(E10<>"",N(E10),IFERROR(N(INDEX(Activities!$I$2:$I$201,MATCH($A10,Activities!$A$2:$A$201,0))),0)))) | L10: =IF(AND($A10="",$B10=""),"",IF(ISNA(MATCH($A10,Activities!$A$2:$A$201,0)),"Unknown activity",IF(ISNA(MATCH($B10,Students!$A$2:$A$301,0)),"Unknown student",IF(D10="","No status",IF(COUNTIFS($A$2:$A$1001,$A10,$B$2:$B$1001,$B10)>1,"Duplicate",IF(AND(D10<>"Withdrawn",G10<>"",COUNTIFS($B$2:$B$1001,$B10,$G$2:$G$1001,G10,$D$2:$D$1001,"<>Withdrawn")>1),"Same-day clash","OK"))))))
G11: =IF($A11="","",IFERROR(IF(INDEX(Activities!$C$2:$C$201,MATCH($A11,Activities!$A$2:$A$201,0))="","",INDEX(Activities!$C$2:$C$201,MATCH($A11,Activities!$A$2:$A$201,0))),"")) | H11: =IF($A11="","",IFERROR(IF(INDEX(Activities!$B$2:$B$201,MATCH($A11,Activities!$A$2:$A$201,0))="","",INDEX(Activities!$B$2:$B$201,MATCH($A11,Activities!$A$2:$A$201,0))),"")) | I11: =IF($B11="","",IFERROR(IF(INDEX(Students!$C$2:$C$301,MATCH($B11,Students!$A$2:$A$301,0))="","",INDEX(Students!$C$2:$C$301,MATCH($B11,Students!$A$2:$A$301,0))),"")) | J11: =IF($B11="","",IFERROR(IF(INDEX(Students!$B$2:$B$301,MATCH($B11,Students!$A$2:$A$301,0))="","",INDEX(Students!$B$2:$B$301,MATCH($B11,Students!$A$2:$A$301,0))),"")) | K11: =IF($A11="","",IF(D11="Withdrawn",0,IF(E11<>"",N(E11),IFERROR(N(INDEX(Activities!$I$2:$I$201,MATCH($A11,Activities!$A$2:$A$201,0))),0)))) | L11: =IF(AND($A11="",$B11=""),"",IF(ISNA(MATCH($A11,Activities!$A$2:$A$201,0)),"Unknown activity",IF(ISNA(MATCH($B11,Students!$A$2:$A$301,0)),"Unknown student",IF(D11="","No status",IF(COUNTIFS($A$2:$A$1001,$A11,$B$2:$B$1001,$B11)>1,"Duplicate",IF(AND(D11<>"Withdrawn",G11<>"",COUNTIFS($B$2:$B$1001,$B11,$G$2:$G$1001,G11,$D$2:$D$1001,"<>Withdrawn")>1),"Same-day clash","OK"))))))
G12: =IF($A12="","",IFERROR(IF(INDEX(Activities!$C$2:$C$201,MATCH($A12,Activities!$A$2:$A$201,0))="","",INDEX(Activities!$C$2:$C$201,MATCH($A12,Activities!$A$2:$A$201,0))),"")) | H12: =IF($A12="","",IFERROR(IF(INDEX(Activities!$B$2:$B$201,MATCH($A12,Activities!$A$2:$A$201,0))="","",INDEX(Activities!$B$2:$B$201,MATCH($A12,Activities!$A$2:$A$201,0))),"")) | I12: =IF($B12="","",IFERROR(IF(INDEX(Students!$C$2:$C$301,MATCH($B12,Students!$A$2:$A$301,0))="","",INDEX(Students!$C$2:$C$301,MATCH($B12,Students!$A$2:$A$301,0))),"")) | J12: =IF($B12="","",IFERROR(IF(INDEX(Students!$B$2:$B$301,MATCH($B12,Students!$A$2:$A$301,0))="","",INDEX(Students!$B$2:$B$301,MATCH($B12,Students!$A$2:$A$301,0))),"")) | K12: =IF($A12="","",IF(D12="Withdrawn",0,IF(E12<>"",N(E12),IFERROR(N(INDEX(Activities!$I$2:$I$201,MATCH($A12,Activities!$A$2:$A$201,0))),0)))) | L12: =IF(AND($A12="",$B12=""),"",IF(ISNA(MATCH($A12,Activities!$A$2:$A$201,0)),"Unknown activity",IF(ISNA(MATCH($B12,Students!$A$2:$A$301,0)),"Unknown student",IF(D12="","No status",IF(COUNTIFS($A$2:$A$1001,$A12,$B$2:$B$1001,$B12)>1,"Duplicate",IF(AND(D12<>"Withdrawn",G12<>"",COUNTIFS($B$2:$B$1001,$B12,$G$2:$G$1001,G12,$D$2:$D$1001,"<>Withdrawn")>1),"Same-day clash","OK"))))))
G13: =IF($A13="","",IFERROR(IF(INDEX(Activities!$C$2:$C$201,MATCH($A13,Activities!$A$2:$A$201,0))="","",INDEX(Activities!$C$2:$C$201,MATCH($A13,Activities!$A$2:$A$201,0))),"")) | H13: =IF($A13="","",IFERROR(IF(INDEX(Activities!$B$2:$B$201,MATCH($A13,Activities!$A$2:$A$201,0))="","",INDEX(Activities!$B$2:$B$201,MATCH($A13,Activities!$A$2:$A$201,0))),"")) | I13: =IF($B13="","",IFERROR(IF(INDEX(Students!$C$2:$C$301,MATCH($B13,Students!$A$2:$A$301,0))="","",INDEX(Students!$C$2:$C$301,MATCH($B13,Students!$A$2:$A$301,0))),"")) | J13: =IF($B13="","",IFERROR(IF(INDEX(Students!$B$2:$B$301,MATCH($B13,Students!$A$2:$A$301,0))="","",INDEX(Students!$B$2:$B$301,MATCH($B13,Students!$A$2:$A$301,0))),"")) | K13: =IF($A13="","",IF(D13="Withdrawn",0,IF(E13<>"",N(E13),IFERROR(N(INDEX(Activities!$I$2:$I$201,MATCH($A13,Activities!$A$2:$A$201,0))),0)))) | L13: =IF(AND($A13="",$B13=""),"",IF(ISNA(MATCH($A13,Activities!$A$2:$A$201,0)),"Unknown activity",IF(ISNA(MATCH($B13,Students!$A$2:$A$301,0)),"Unknown student",IF(D13="","No status",IF(COUNTIFS($A$2:$A$1001,$A13,$B$2:$B$1001,$B13)>1,"Duplicate",IF(AND(D13<>"Withdrawn",G13<>"",COUNTIFS($B$2:$B$1001,$B13,$G$2:$G$1001,G13,$D$2:$D$1001,"<>Withdrawn")>1),"Same-day clash","OK"))))))
G14: =IF($A14="","",IFERROR(IF(INDEX(Activities!$C$2:$C$201,MATCH($A14,Activities!$A$2:$A$201,0))="","",INDEX(Activities!$C$2:$C$201,MATCH($A14,Activities!$A$2:$A$201,0))),"")) | H14: =IF($A14="","",IFERROR(IF(INDEX(Activities!$B$2:$B$201,MATCH($A14,Activities!$A$2:$A$201,0))="","",INDEX(Activities!$B$2:$B$201,MATCH($A14,Activities!$A$2:$A$201,0))),"")) | I14: =IF($B14="","",IFERROR(IF(INDEX(Students!$C$2:$C$301,MATCH($B14,Students!$A$2:$A$301,0))="","",INDEX(Students!$C$2:$C$301,MATCH($B14,Students!$A$2:$A$301,0))),"")) | J14: =IF($B14="","",IFERROR(IF(INDEX(Students!$B$2:$B$301,MATCH($B14,Students!$A$2:$A$301,0))="","",INDEX(Students!$B$2:$B$301,MATCH($B14,Students!$A$2:$A$301,0))),"")) | K14: =IF($A14="","",IF(D14="Withdrawn",0,IF(E14<>"",N(E14),IFERROR(N(INDEX(Activities!$I$2:$I$201,MATCH($A14,Activities!$A$2:$A$201,0))),0)))) | L14: =IF(AND($A14="",$B14=""),"",IF(ISNA(MATCH($A14,Activities!$A$2:$A$201,0)),"Unknown activity",IF(ISNA(MATCH($B14,Students!$A$2:$A$301,0)),"Unknown student",IF(D14="","No status",IF(COUNTIFS($A$2:$A$1001,$A14,$B$2:$B$1001,$B14)>1,"Duplicate",IF(AND(D14<>"Withdrawn",G14<>"",COUNTIFS($B$2:$B$1001,$B14,$G$2:$G$1001,G14,$D$2:$D$1001,"<>Withdrawn")>1),"Same-day clash","OK"))))))
... G1001: =IF($A1001="","",IFERROR(IF(INDEX(Activities!$C$2:$C$201,MATCH($A1001,Activities!$A$2:$A$201,0))="","",INDEX(Activities!$C$2:$C$201,MATCH($A1001,Activities!$A$2:$A$201,0))),"")) | H1001: =IF($A1001="","",IFERROR(IF(INDEX(Activities!$B$2:$B$201,MATCH($A1001,Activities!$A$2:$A$201,0))="","",INDEX(Activities!$B$2:$B$201,MATCH($A1001,Activities!$A$2:$A$201,0))),"")) | I1001: =IF($B1001="","",IFERROR(IF(INDEX(Students!$C$2:$C$301,MATCH($B1001,Students!$A$2:$A$301,0))="","",INDEX(Students!$C$2:$C$301,MATCH($B1001,Students!$A$2:$A$301,0))),"")) | J1001: =IF($B1001="","",IFERROR(IF(INDEX(Students!$B$2:$B$301,MATCH($B1001,Students!$A$2:$A$301,0))="","",INDEX(Students!$B$2:$B$301,MATCH($B1001,Students!$A$2:$A$301,0))),"")) | K1001: =IF($A1001="","",IF(D1001="Withdrawn",0,IF(E1001<>"",N(E1001),IFERROR(N(INDEX(Activities!$I$2:$I$201,MATCH($A1001,Activities!$A$2:$A$201,0))),0)))) | L1001: =IF(AND($A1001="",$B1001=""),"",IF(ISNA(MATCH($A1001,Activities!$A$2:$A$201,0)),"Unknown activity",IF(ISNA(MATCH($B1001,Students!$A$2:$A$301,0)),"Unknown student",IF(D1001="","No status",IF(COUNTIFS($A$2:$A$1001,$A1001,$B$2:$B$1001,$B1001)>1,"Duplicate",IF(AND(D1001<>"Withdrawn",G1001<>"",COUNTIFS($B$2:$B$1001,$B1001,$G$2:$G$1001,G1001,$D$2:$D$1001,"<>Withdrawn")>1),"Same-day clash","OK"))))))

Sheet Activities
A1: Activity | B1: Category | C1: Date | D1: Start | E1: End | F1: Venue | G1: Teacher-in-Charge | H1: Leaders Needed | I1: Hours (auto) | J1: Assigned | K1: Open Slots | L1: Fill % | M1: Staffing Status | N1: Timing | O1: Sort key (auto)
A2: Speech Day & Prize Giving | B2: Ceremony | C2: 46311 | D2: 0.33333333 | E2: 0.47916667 | F2: School Hall | G2: Mr Lim K. H. | H2: 12 | I2: =IF(OR(D2="",E2=""),"",ROUND(MOD(E2-D2,1)*24,2)) -> 3.5 | J2: =IF($A2="","",COUNTIFS(Deployments!$A$2:$A$1001,$A2,Deployments!$D$2:$D$1001,"<>Withdrawn")) -> 1 | K2: =IF($A2="","",MAX(0,N(H2)-J2)) -> 11 | L2: =IF(OR($A2="",N(H2)=0),"",J2/H2) -> 0.083333333 | M2: =IF($A2="","",IF(N(H2)=0,"No target",IF(J2>H2,"Over-staffed",IF(J2=H2,"Fully staffed",IF(J2=0,"Unstaffed","Short"))))) -> Short | N2: =IF(OR($A2="",C2=""),"",IF(C2<TODAY(),"Past",IF(C2-TODAY()<=Setup!$H$3,"Upcoming","Later"))) -> Past | O2: =IF($A2="","",IF(C2="",100000,C2)+ROW()/100000) -> 46311
I3: =IF(OR(D3="",E3=""),"",ROUND(MOD(E3-D3,1)*24,2)) | J3: =IF($A3="","",COUNTIFS(Deployments!$A$2:$A$1001,$A3,Deployments!$D$2:$D$1001,"<>Withdrawn")) | K3: =IF($A3="","",MAX(0,N(H3)-J3)) | L3: =IF(OR($A3="",N(H3)=0),"",J3/H3) | M3: =IF($A3="","",IF(N(H3)=0,"No target",IF(J3>H3,"Over-staffed",IF(J3=H3,"Fully staffed",IF(J3=0,"Unstaffed","Short"))))) | N3: =IF(OR($A3="",C3=""),"",IF(C3<TODAY(),"Past",IF(C3-TODAY()<=Setup!$H$3,"Upcoming","Later"))) | O3: =IF($A3="","",IF(C3="",100000,C3)+ROW()/100000)
I4: =IF(OR(D4="",E4=""),"",ROUND(MOD(E4-D4,1)*24,2)) | J4: =IF($A4="","",COUNTIFS(Deployments!$A$2:$A$1001,$A4,Deployments!$D$2:$D$1001,"<>Withdrawn")) | K4: =IF($A4="","",MAX(0,N(H4)-J4)) | L4: =IF(OR($A4="",N(H4)=0),"",J4/H4) | M4: =IF($A4="","",IF(N(H4)=0,"No target",IF(J4>H4,"Over-staffed",IF(J4=H4,"Fully staffed",IF(J4=0,"Unstaffed","Short"))))) | N4: =IF(OR($A4="",C4=""),"",IF(C4<TODAY(),"Past",IF(C4-TODAY()<=Setup!$H$3,"Upcoming","Later"))) | O4: =IF($A4="","",IF(C4="",100000,C4)+ROW()/100000)
I5: =IF(OR(D5="",E5=""),"",ROUND(MOD(E5-D5,1)*24,2)) | J5: =IF($A5="","",COUNTIFS(Deployments!$A$2:$A$1001,$A5,Deployments!$D$2:$D$1001,"<>Withdrawn")) | K5: =IF($A5="","",MAX(0,N(H5)-J5)) | L5: =IF(OR($A5="",N(H5)=0),"",J5/H5) | M5: =IF($A5="","",IF(N(H5)=0,"No target",IF(J5>H5,"Over-staffed",IF(J5=H5,"Fully staffed",IF(J5=0,"Unstaffed","Short"))))) | N5: =IF(OR($A5="",C5=""),"",IF(C5<TODAY(),"Past",IF(C5-TODAY()<=Setup!$H$3,"Upcoming","Later"))) | O5: =IF($A5="","",IF(C5="",100000,C5)+ROW()/100000)
I6: =IF(OR(D6="",E6=""),"",ROUND(MOD(E6-D6,1)*24,2)) | J6: =IF($A6="","",COUNTIFS(Deployments!$A$2:$A$1001,$A6,Deployments!$D$2:$D$1001,"<>Withdrawn")) | K6: =IF($A6="","",MAX(0,N(H6)-J6)) | L6: =IF(OR($A6="",N(H6)=0),"",J6/H6) | M6: =IF($A6="","",IF(N(H6)=0,"No target",IF(J6>H6,"Over-staffed",IF(J6=H6,"Fully staffed",IF(J6=0,"Unstaffed","Short"))))) | N6: =IF(OR($A6="",C6=""),"",IF(C6<TODAY(),"Past",IF(C6-TODAY()<=Setup!$H$3,"Upcoming","Later"))) | O6: =IF($A6="","",IF(C6="",100000,C6)+ROW()/100000)
I7: =IF(OR(D7="",E7=""),"",ROUND(MOD(E7-D7,1)*24,2)) | J7: =IF($A7="","",COUNTIFS(Deployments!$A$2:$A$1001,$A7,Deployments!$D$2:$D$1001,"<>Withdrawn")) | K7: =IF($A7="","",MAX(0,N(H7)-J7)) | L7: =IF(OR($A7="",N(H7)=0),"",J7/H7) | M7: =IF($A7="","",IF(N(H7)=0,"No target",IF(J7>H7,"Over-staffed",IF(J7=H7,"Fully staffed",IF(J7=0,"Unstaffed","Short"))))) | N7: =IF(OR($A7="",C7=""),"",IF(C7<TODAY(),"Past",IF(C7-TODAY()<=Setup!$H$3,"Upcoming","Later"))) | O7: =IF($A7="","",IF(C7="",100000,C7)+ROW()/100000)
I8: =IF(OR(D8="",E8=""),"",ROUND(MOD(E8-D8,1)*24,2)) | J8: =IF($A8="","",COUNTIFS(Deployments!$A$2:$A$1001,$A8,Deployments!$D$2:$D$1001,"<>Withdrawn")) | K8: =IF($A8="","",MAX(0,N(H8)-J8)) | L8: =IF(OR($A8="",N(H8)=0),"",J8/H8) | M8: =IF($A8="","",IF(N(H8)=0,"No target",IF(J8>H8,"Over-staffed",IF(J8=H8,"Fully staffed",IF(J8=0,"Unstaffed","Short"))))) | N8: =IF(OR($A8="",C8=""),"",IF(C8<TODAY(),"Past",IF(C8-TODAY()<=Setup!$H$3,"Upcoming","Later"))) | O8: =IF($A8="","",IF(C8="",100000,C8)+ROW()/100000)
I9: =IF(OR(D9="",E9=""),"",ROUND(MOD(E9-D9,1)*24,2)) | J9: =IF($A9="","",COUNTIFS(Deployments!$A$2:$A$1001,$A9,Deployments!$D$2:$D$1001,"<>Withdrawn")) | K9: =IF($A9="","",MAX(0,N(H9)-J9)) | L9: =IF(OR($A9="",N(H9)=0),"",J9/H9) | M9: =IF($A9="","",IF(N(H9)=0,"No target",IF(J9>H9,"Over-staffed",IF(J9=H9,"Fully staffed",IF(J9=0,"Unstaffed","Short"))))) | N9: =IF(OR($A9="",C9=""),"",IF(C9<TODAY(),"Past",IF(C9-TODAY()<=Setup!$H$3,"Upcoming","Later"))) | O9: =IF($A9="","",IF(C9="",100000,C9)+ROW()/100000)
I10: =IF(OR(D10="",E10=""),"",ROUND(MOD(E10-D10,1)*24,2)) | J10: =IF($A10="","",COUNTIFS(Deployments!$A$2:$A$1001,$A10,Deployments!$D$2:$D$1001,"<>Withdrawn")) | K10: =IF($A10="","",MAX(0,N(H10)-J10)) | L10: =IF(OR($A10="",N(H10)=0),"",J10/H10) | M10: =IF($A10="","",IF(N(H10)=0,"No target",IF(J10>H10,"Over-staffed",IF(J10=H10,"Fully staffed",IF(J10=0,"Unstaffed","Short"))))) | N10: =IF(OR($A10="",C10=""),"",IF(C10<TODAY(),"Past",IF(C10-TODAY()<=Setup!$H$3,"Upcoming","Later"))) | O10: =IF($A10="","",IF(C10="",100000,C10)+ROW()/100000)
I11: =IF(OR(D11="",E11=""),"",ROUND(MOD(E11-D11,1)*24,2)) | J11: =IF($A11="","",COUNTIFS(Deployments!$A$2:$A$1001,$A11,Deployments!$D$2:$D$1001,"<>Withdrawn")) | K11: =IF($A11="","",MAX(0,N(H11)-J11)) | L11: =IF(OR($A11="",N(H11)=0),"",J11/H11) | M11: =IF($A11="","",IF(N(H11)=0,"No target",IF(J11>H11,"Over-staffed",IF(J11=H11,"Fully staffed",IF(J11=0,"Unstaffed","Short"))))) | N11: =IF(OR($A11="",C11=""),"",IF(C11<TODAY(),"Past",IF(C11-TODAY()<=Setup!$H$3,"Upcoming","Later"))) | O11: =IF($A11="","",IF(C11="",100000,C11)+ROW()/100000)
I12: =IF(OR(D12="",E12=""),"",ROUND(MOD(E12-D12,1)*24,2)) | J12: =IF($A12="","",COUNTIFS(Deployments!$A$2:$A$1001,$A12,Deployments!$D$2:$D$1001,"<>Withdrawn")) | K12: =IF($A12="","",MAX(0,N(H12)-J12)) | L12: =IF(OR($A12="",N(H12)=0),"",J12/H12) | M12: =IF($A12="","",IF(N(H12)=0,"No target",IF(J12>H12,"Over-staffed",IF(J12=H12,"Fully staffed",IF(J12=0,"Unstaffed","Short"))))) | N12: =IF(OR($A12="",C12=""),"",IF(C12<TODAY(),"Past",IF(C12-TODAY()<=Setup!$H$3,"Upcoming","Later"))) | O12: =IF($A12="","",IF(C12="",100000,C12)+ROW()/100000)
I13: =IF(OR(D13="",E13=""),"",ROUND(MOD(E13-D13,1)*24,2)) | J13: =IF($A13="","",COUNTIFS(Deployments!$A$2:$A$1001,$A13,Deployments!$D$2:$D$1001,"<>Withdrawn")) | K13: =IF($A13="","",MAX(0,N(H13)-J13)) | L13: =IF(OR($A13="",N(H13)=0),"",J13/H13) | M13: =IF($A13="","",IF(N(H13)=0,"No target",IF(J13>H13,"Over-staffed",IF(J13=H13,"Fully staffed",IF(J13=0,"Unstaffed","Short"))))) | N13: =IF(OR($A13="",C13=""),"",IF(C13<TODAY(),"Past",IF(C13-TODAY()<=Setup!$H$3,"Upcoming","Later"))) | O13: =IF($A13="","",IF(C13="",100000,C13)+ROW()/100000)
I14: =IF(OR(D14="",E14=""),"",ROUND(MOD(E14-D14,1)*24,2)) | J14: =IF($A14="","",COUNTIFS(Deployments!$A$2:$A$1001,$A14,Deployments!$D$2:$D$1001,"<>Withdrawn")) | K14: =IF($A14="","",MAX(0,N(H14)-J14)) | L14: =IF(OR($A14="",N(H14)=0),"",J14/H14) | M14: =IF($A14="","",IF(N(H14)=0,"No target",IF(J14>H14,"Over-staffed",IF(J14=H14,"Fully staffed",IF(J14=0,"Unstaffed","Short"))))) | N14: =IF(OR($A14="",C14=""),"",IF(C14<TODAY(),"Past",IF(C14-TODAY()<=Setup!$H$3,"Upcoming","Later"))) | O14: =IF($A14="","",IF(C14="",100000,C14)+ROW()/100000)
... I201: =IF(OR(D201="",E201=""),"",ROUND(MOD(E201-D201,1)*24,2)) | J201: =IF($A201="","",COUNTIFS(Deployments!$A$2:$A$1001,$A201,Deployments!$D$2:$D$1001,"<>Withdrawn")) | K201: =IF($A201="","",MAX(0,N(H201)-J201)) | L201: =IF(OR($A201="",N(H201)=0),"",J201/H201) | M201: =IF($A201="","",IF(N(H201)=0,"No target",IF(J201>H201,"Over-staffed",IF(J201=H201,"Fully staffed",IF(J201=0,"Unstaffed","Short"))))) | N201: =IF(OR($A201="",C201=""),"",IF(C201<TODAY(),"Past",IF(C201-TODAY()<=Setup!$H$3,"Upcoming","Later"))) | O201: =IF($A201="","",IF(C201="",100000,C201)+ROW()/100000)

Sheet Students
A1: Full Name | B1: Name (preferred) | C1: Form Class | D1: Leadership Group | E1: Notes | F1: Deployments | G1: Leader-Hours | H1: Latest Activity | I1: Load Status | J1: Rank key (auto) | K1: Undeployed # (auto)
A2: Tan Wei Ling | B2: Wei Ling | C2: 303 | D2: Prefect | F2: =IF($A2="","",COUNTIFS(Deployments!$B$2:$B$1001,$A2,Deployments!$D$2:$D$1001,"<>Withdrawn")) -> 1 | G2: =IF($A2="","",SUMIFS(Deployments!$K$2:$K$1001,Deployments!$B$2:$B$1001,$A2)) -> 3.5 | H2: =IF(N(F2)=0,"",IF(_xlfn.MAXIFS(Deployments!$G$2:$G$1001,Deployments!$B$2:$B$1001,$A2,Deployments!$D$2:$D$1001,"<>Withdrawn")=0,"",_xlfn.MAXIFS(Deployments!$G$2:$G$1001,Deployments!$B$2:$B$1001,$A2,Deployments!$D$2:$D$1001,"<>Withdrawn"))) -> 46311 | I2: =IF($A2="","",IF(F2=0,"Not deployed",IF(F2>=Setup!$H$2,"High load","Deployed"))) -> Deployed | J2: =IF(N(F2)=0,"",F2+MIN(G2,999)/1000+(1000-ROW())/10000000) -> 1.0035998 | K2: =IF(I2="Not deployed",COUNTIF($I$2:I2,"Not deployed"),"")
F3: =IF($A3="","",COUNTIFS(Deployments!$B$2:$B$1001,$A3,Deployments!$D$2:$D$1001,"<>Withdrawn")) | G3: =IF($A3="","",SUMIFS(Deployments!$K$2:$K$1001,Deployments!$B$2:$B$1001,$A3)) | H3: =IF(N(F3)=0,"",IF(_xlfn.MAXIFS(Deployments!$G$2:$G$1001,Deployments!$B$2:$B$1001,$A3,Deployments!$D$2:$D$1001,"<>Withdrawn")=0,"",_xlfn.MAXIFS(Deployments!$G$2:$G$1001,Deployments!$B$2:$B$1001,$A3,Deployments!$D$2:$D$1001,"<>Withdrawn"))) | I3: =IF($A3="","",IF(F3=0,"Not deployed",IF(F3>=Setup!$H$2,"High load","Deployed"))) | J3: =IF(N(F3)=0,"",F3+MIN(G3,999)/1000+(1000-ROW())/10000000) | K3: =IF(I3="Not deployed",COUNTIF($I$2:I3,"Not deployed"),"")
F4: =IF($A4="","",COUNTIFS(Deployments!$B$2:$B$1001,$A4,Deployments!$D$2:$D$1001,"<>Withdrawn")) | G4: =IF($A4="","",SUMIFS(Deployments!$K$2:$K$1001,Deployments!$B$2:$B$1001,$A4)) | H4: =IF(N(F4)=0,"",IF(_xlfn.MAXIFS(Deployments!$G$2:$G$1001,Deployments!$B$2:$B$1001,$A4,Deployments!$D$2:$D$1001,"<>Withdrawn")=0,"",_xlfn.MAXIFS(Deployments!$G$2:$G$1001,Deployments!$B$2:$B$1001,$A4,Deployments!$D$2:$D$1001,"<>Withdrawn"))) | I4: =IF($A4="","",IF(F4=0,"Not deployed",IF(F4>=Setup!$H$2,"High load","Deployed"))) | J4: =IF(N(F4)=0,"",F4+MIN(G4,999)/1000+(1000-ROW())/10000000) | K4: =IF(I4="Not deployed",COUNTIF($I$2:I4,"Not deployed"),"")
F5: =IF($A5="","",COUNTIFS(Deployments!$B$2:$B$1001,$A5,Deployments!$D$2:$D$1001,"<>Withdrawn")) | G5: =IF($A5="","",SUMIFS(Deployments!$K$2:$K$1001,Deployments!$B$2:$B$1001,$A5)) | H5: =IF(N(F5)=0,"",IF(_xlfn.MAXIFS(Deployments!$G$2:$G$1001,Deployments!$B$2:$B$1001,$A5,Deployments!$D$2:$D$1001,"<>Withdrawn")=0,"",_xlfn.MAXIFS(Deployments!$G$2:$G$1001,Deployments!$B$2:$B$1001,$A5,Deployments!$D$2:$D$1001,"<>Withdrawn"))) | I5: =IF($A5="","",IF(F5=0,"Not deployed",IF(F5>=Setup!$H$2,"High load","Deployed"))) | J5: =IF(N(F5)=0,"",F5+MIN(G5,999)/1000+(1000-ROW())/10000000) | K5: =IF(I5="Not deployed",COUNTIF($I$2:I5,"Not deployed"),"")
F6: =IF($A6="","",COUNTIFS(Deployments!$B$2:$B$1001,$A6,Deployments!$D$2:$D$1001,"<>Withdrawn")) | G6: =IF($A6="","",SUMIFS(Deployments!$K$2:$K$1001,Deployments!$B$2:$B$1001,$A6)) | H6: =IF(N(F6)=0,"",IF(_xlfn.MAXIFS(Deployments!$G$2:$G$1001,Deployments!$B$2:$B$1001,$A6,Deployments!$D$2:$D$1001,"<>Withdrawn")=0,"",_xlfn.MAXIFS(Deployments!$G$2:$G$1001,Deployments!$B$2:$B$1001,$A6,Deployments!$D$2:$D$1001,"<>Withdrawn"))) | I6: =IF($A6="","",IF(F6=0,"Not deployed",IF(F6>=Setup!$H$2,"High load","Deployed"))) | J6: =IF(N(F6)=0,"",F6+MIN(G6,999)/1000+(1000-ROW())/10000000) | K6: =IF(I6="Not deployed",COUNTIF($I$2:I6,"Not deployed"),"")
F7: =IF($A7="","",COUNTIFS(Deployments!$B$2:$B$1001,$A7,Deployments!$D$2:$D$1001,"<>Withdrawn")) | G7: =IF($A7="","",SUMIFS(Deployments!$K$2:$K$1001,Deployments!$B$2:$B$1001,$A7)) | H7: =IF(N(F7)=0,"",IF(_xlfn.MAXIFS(Deployments!$G$2:$G$1001,Deployments!$B$2:$B$1001,$A7,Deployments!$D$2:$D$1001,"<>Withdrawn")=0,"",_xlfn.MAXIFS(Deployments!$G$2:$G$1001,Deployments!$B$2:$B$1001,$A7,Deployments!$D$2:$D$1001,"<>Withdrawn"))) | I7: =IF($A7="","",IF(F7=0,"Not deployed",IF(F7>=Setup!$H$2,"High load","Deployed"))) | J7: =IF(N(F7)=0,"",F7+MIN(G7,999)/1000+(1000-ROW())/10000000) | K7: =IF(I7="Not deployed",COUNTIF($I$2:I7,"Not deployed"),"")
F8: =IF($A8="","",COUNTIFS(Deployments!$B$2:$B$1001,$A8,Deployments!$D$2:$D$1001,"<>Withdrawn")) | G8: =IF($A8="","",SUMIFS(Deployments!$K$2:$K$1001,Deployments!$B$2:$B$1001,$A8)) | H8: =IF(N(F8)=0,"",IF(_xlfn.MAXIFS(Deployments!$G$2:$G$1001,Deployments!$B$2:$B$1001,$A8,Deployments!$D$2:$D$1001,"<>Withdrawn")=0,"",_xlfn.MAXIFS(Deployments!$G$2:$G$1001,Deployments!$B$2:$B$1001,$A8,Deployments!$D$2:$D$1001,"<>Withdrawn"))) | I8: =IF($A8="","",IF(F8=0,"Not deployed",IF(F8>=Setup!$H$2,"High load","Deployed"))) | J8: =IF(N(F8)=0,"",F8+MIN(G8,999)/1000+(1000-ROW())/10000000) | K8: =IF(I8="Not deployed",COUNTIF($I$2:I8,"Not deployed"),"")
F9: =IF($A9="","",COUNTIFS(Deployments!$B$2:$B$1001,$A9,Deployments!$D$2:$D$1001,"<>Withdrawn")) | G9: =IF($A9="","",SUMIFS(Deployments!$K$2:$K$1001,Deployments!$B$2:$B$1001,$A9)) | H9: =IF(N(F9)=0,"",IF(_xlfn.MAXIFS(Deployments!$G$2:$G$1001,Deployments!$B$2:$B$1001,$A9,Deployments!$D$2:$D$1001,"<>Withdrawn")=0,"",_xlfn.MAXIFS(Deployments!$G$2:$G$1001,Deployments!$B$2:$B$1001,$A9,Deployments!$D$2:$D$1001,"<>Withdrawn"))) | I9: =IF($A9="","",IF(F9=0,"Not deployed",IF(F9>=Setup!$H$2,"High load","Deployed"))) | J9: =IF(N(F9)=0,"",F9+MIN(G9,999)/1000+(1000-ROW())/10000000) | K9: =IF(I9="Not deployed",COUNTIF($I$2:I9,"Not deployed"),"")
F10: =IF($A10="","",COUNTIFS(Deployments!$B$2:$B$1001,$A10,Deployments!$D$2:$D$1001,"<>Withdrawn")) | G10: =IF($A10="","",SUMIFS(Deployments!$K$2:$K$1001,Deployments!$B$2:$B$1001,$A10)) | H10: =IF(N(F10)=0,"",IF(_xlfn.MAXIFS(Deployments!$G$2:$G$1001,Deployments!$B$2:$B$1001,$A10,Deployments!$D$2:$D$1001,"<>Withdrawn")=0,"",_xlfn.MAXIFS(Deployments!$G$2:$G$1001,Deployments!$B$2:$B$1001,$A10,Deployments!$D$2:$D$1001,"<>Withdrawn"))) | I10: =IF($A10="","",IF(F10=0,"Not deployed",IF(F10>=Setup!$H$2,"High load","Deployed"))) | J10: =IF(N(F10)=0,"",F10+MIN(G10,999)/1000+(1000-ROW())/10000000) | K10: =IF(I10="Not deployed",COUNTIF($I$2:I10,"Not deployed"),"")
F11: =IF($A11="","",COUNTIFS(Deployments!$B$2:$B$1001,$A11,Deployments!$D$2:$D$1001,"<>Withdrawn")) | G11: =IF($A11="","",SUMIFS(Deployments!$K$2:$K$1001,Deployments!$B$2:$B$1001,$A11)) | H11: =IF(N(F11)=0,"",IF(_xlfn.MAXIFS(Deployments!$G$2:$G$1001,Deployments!$B$2:$B$1001,$A11,Deployments!$D$2:$D$1001,"<>Withdrawn")=0,"",_xlfn.MAXIFS(Deployments!$G$2:$G$1001,Deployments!$B$2:$B$1001,$A11,Deployments!$D$2:$D$1001,"<>Withdrawn"))) | I11: =IF($A11="","",IF(F11=0,"Not deployed",IF(F11>=Setup!$H$2,"High load","Deployed"))) | J11: =IF(N(F11)=0,"",F11+MIN(G11,999)/1000+(1000-ROW())/10000000) | K11: =IF(I11="Not deployed",COUNTIF($I$2:I11,"Not deployed"),"")
F12: =IF($A12="","",COUNTIFS(Deployments!$B$2:$B$1001,$A12,Deployments!$D$2:$D$1001,"<>Withdrawn")) | G12: =IF($A12="","",SUMIFS(Deployments!$K$2:$K$1001,Deployments!$B$2:$B$1001,$A12)) | H12: =IF(N(F12)=0,"",IF(_xlfn.MAXIFS(Deployments!$G$2:$G$1001,Deployments!$B$2:$B$1001,$A12,Deployments!$D$2:$D$1001,"<>Withdrawn")=0,"",_xlfn.MAXIFS(Deployments!$G$2:$G$1001,Deployments!$B$2:$B$1001,$A12,Deployments!$D$2:$D$1001,"<>Withdrawn"))) | I12: =IF($A12="","",IF(F12=0,"Not deployed",IF(F12>=Setup!$H$2,"High load","Deployed"))) | J12: =IF(N(F12)=0,"",F12+MIN(G12,999)/1000+(1000-ROW())/10000000) | K12: =IF(I12="Not deployed",COUNTIF($I$2:I12,"Not deployed"),"")
F13: =IF($A13="","",COUNTIFS(Deployments!$B$2:$B$1001,$A13,Deployments!$D$2:$D$1001,"<>Withdrawn")) | G13: =IF($A13="","",SUMIFS(Deployments!$K$2:$K$1001,Deployments!$B$2:$B$1001,$A13)) | H13: =IF(N(F13)=0,"",IF(_xlfn.MAXIFS(Deployments!$G$2:$G$1001,Deployments!$B$2:$B$1001,$A13,Deployments!$D$2:$D$1001,"<>Withdrawn")=0,"",_xlfn.MAXIFS(Deployments!$G$2:$G$1001,Deployments!$B$2:$B$1001,$A13,Deployments!$D$2:$D$1001,"<>Withdrawn"))) | I13: =IF($A13="","",IF(F13=0,"Not deployed",IF(F13>=Setup!$H$2,"High load","Deployed"))) | J13: =IF(N(F13)=0,"",F13+MIN(G13,999)/1000+(1000-ROW())/10000000) | K13: =IF(I13="Not deployed",COUNTIF($I$2:I13,"Not deployed"),"")
F14: =IF($A14="","",COUNTIFS(Deployments!$B$2:$B$1001,$A14,Deployments!$D$2:$D$1001,"<>Withdrawn")) | G14: =IF($A14="","",SUMIFS(Deployments!$K$2:$K$1001,Deployments!$B$2:$B$1001,$A14)) | H14: =IF(N(F14)=0,"",IF(_xlfn.MAXIFS(Deployments!$G$2:$G$1001,Deployments!$B$2:$B$1001,$A14,Deployments!$D$2:$D$1001,"<>Withdrawn")=0,"",_xlfn.MAXIFS(Deployments!$G$2:$G$1001,Deployments!$B$2:$B$1001,$A14,Deployments!$D$2:$D$1001,"<>Withdrawn"))) | I14: =IF($A14="","",IF(F14=0,"Not deployed",IF(F14>=Setup!$H$2,"High load","Deployed"))) | J14: =IF(N(F14)=0,"",F14+MIN(G14,999)/1000+(1000-ROW())/10000000) | K14: =IF(I14="Not deployed",COUNTIF($I$2:I14,"Not deployed"),"")
... F301: =IF($A301="","",COUNTIFS(Deployments!$B$2:$B$1001,$A301,Deployments!$D$2:$D$1001,"<>Withdrawn")) | G301: =IF($A301="","",SUMIFS(Deployments!$K$2:$K$1001,Deployments!$B$2:$B$1001,$A301)) | H301: =IF(N(F301)=0,"",IF(_xlfn.MAXIFS(Deployments!$G$2:$G$1001,Deployments!$B$2:$B$1001,$A301,Deployments!$D$2:$D$1001,"<>Withdrawn")=0,"",_xlfn.MAXIFS(Deployments!$G$2:$G$1001,Deployments!$B$2:$B$1001,$A301,Deployments!$D$2:$D$1001,"<>Withdrawn"))) | I301: =IF($A301="","",IF(F301=0,"Not deployed",IF(F301>=Setup!$H$2,"High load","Deployed"))) | J301: =IF(N(F301)=0,"",F301+MIN(G301,999)/1000+(1000-ROW())/10000000) | K301: =IF(I301="Not deployed",COUNTIF($I$2:I301,"Not deployed"),"")

Sheet Setup
A1: Categories | B1: Roles | C1: Statuses | D1: Leadership Groups | E1: Form Classes | F1: CCAs | G1: Setting | H1: Value
A2: Ceremony | B2: Emcee | C2: Confirmed | D2: Prefect | E2: 301 | F2: Badminton | G2: High-load threshold (deployments) | H2: 4
A3: School Event | B3: Usher | C3: Tentative | D3: Student Council | E3: 302 | F3: Basketball | G3: "Upcoming" window (days) | H3: 14
A4: Assembly | B4: Marshal | C4: Completed | D4: Class Chairperson | E4: 303 | F4: Football
A5: Sports | B5: Registration | C5: Withdrawn | D5: CCA Leader | E5: 304 | F5: Floorball | G5: Add or rename items in any list above; dropdowns on the input sheets update automatically. Categories feed the Dashboard (first 8 shown); Form Classes feed the Dashboard (first 15 shown).
A6: Community Service | B6: Logistics | D6: Peer Support Leader | E6: 305 | F6: Track & Field
A7: Open House | B7: Facilitator | D7: Sports Leader | F7: Choir
A8: Camp | B8: Group Leader | F8: Concert Band
A9: External | B9: Photographer | F9: Chinese Orchestra
B10: Tech Crew | F10: Malay Dance
F11: Indian Dance
F12: Drama Club
F13: Scouts
F14: Girl Guides
F15: NCC (Land)
F16: NPCC
F17: St John Brigade
F18: Red Cross Youth
F19: Robotics Club
F20: Media Club
F21: Library Club

Sheet Read Me
B1: How to use this workbook
B4: WHAT IT IS
B5: Purpose | C5: Tracks which student leaders are deployed to which school activities, so teachers can staff events fully and spread opportunities fairly. Keep ONE copy on the shared drive and have everyone edit that copy (Excel Online / Google Sheets allow simultaneous editing).
B7: WHERE TO TYPE
B8: Navy column headers | C8: Input columns — type or pick from the dropdown.
B9: Grey column headers | C9: Calculated automatically. Do not type over these cells.
B10: Dashboard | C10: All formulas. Read-only — nothing to enter.
B12: WORKFLOW
B13: 1. Students | C13: One row per student leader: Full Name (must be unique — it is the lookup key), preferred Name, Form Class, Leadership Group. Duplicate names turn red.
B14: 2. Activities | C14: One row per activity: unique Activity name, Category, Date, Start/End time, Venue, Teacher-in-Charge and Leaders Needed. Hours, staffing status and timing are worked out.
B15: 3. Deployments | C15: One row per student per activity. Pick the Activity and Student from the dropdowns, then Role and Status. Leave Hours Override blank to credit the activity's duration. The Check column flags unknown names, duplicates and same-day clashes.
B16: Statuses | C16: Confirmed / Tentative / Completed all count as deployed. Withdrawn rows are kept for the record but excluded from every count and from hours.
B17: 4. Setup | C17: Edit dropdown lists (categories, roles, statuses, leadership groups, form classes) and two settings: the High-load threshold (default 4 deployments) and the Upcoming window (default 14 days).
B19: SHARED-DRIVE TIPS
B20: Renaming | C20: If you rename an activity or student, also update their existing Deployments rows (Check will show "Unknown …" until you do).
B21: Sorting / filtering | C21: Use the filter arrows on each input sheet. Sorting input sheets is safe; the Dashboard re-sorts activities by date on its own.
B22: Capacity | C22: Formulas are pre-filled for 300 students, 200 activities and 1000 deployments. To extend, copy the last grey row down.
B23: Google Sheets | C23: Upload the .xlsx and choose File › Save as Google Sheets for live co-editing; all formulas, dropdowns and colour rules carry over.
B24: New year | C24: Save a copy for the new year, then clear the Deployments and Activities input columns and update the Students list.
B26: Row 2 on each input sheet (yellow) is an example — overwrite or delete it.
